<?xml version="1.0" ?>
<robot name="barista_bot" xmlns:xacro="http://www.ros.org/wiki/xacro">
    <xacro:property name="include_laser" value="true" />

    <!-- Xacro Includes -->

    <xacro:include filename="$(find barista_robot_description)/xacro/drive_wheel.xacro" />
    <xacro:include filename="$(find barista_robot_description)/xacro/caster_wheel.xacro" />
    <xacro:include filename="$(find barista_robot_description)/xacro/standoff_rod.xacro" />
    <xacro:include filename="$(find barista_robot_description)/xacro/cup_holder_tray.xacro" />
    
    <xacro:if value="${include_laser}">
        <xacro:include filename="$(find barista_robot_description)/xacro/laser_scanner.xacro" />
    </xacro:if>

    <!-- Base -->

    <link name="base_link" />

    <joint name="base_barista_body_joint" type="fixed">
        <origin rpy="0 0 0" xyz="0 0 0" />
        <parent link="base_link" />
        <child link="barista_body" />
    </joint>

    <link name="barista_body">
        <visual>
            <origin rpy="0 0 0" xyz="0 0 0.0981" />
            <geometry>
                <cylinder radius="0.179" length="0.155" />
            </geometry>
            <material name="Cyan">
                <color rgba="0 1.0 1.0 1.0"/>
            </material>
        </visual>

        <collision>
            <origin rpy="0 0 0" xyz="0 0 0.0981" />
            <geometry>
                <cylinder radius="0.179" length="0.155" />
            </geometry>
        </collision>

        <inertial>
            <origin rpy="0 0 0" xyz="0 0 0.0981" />
            <mass value="10.0" />
            <inertia ixx="0.100123333" ixy="0" ixz="0" iyy="0.100123333" iyz="0" izz="0.160205" />
        </inertial>
    </link>

    <!-- Laser Scanner -->
    <xacro:if value="${include_laser}">
        <joint name="barista_body_hokuyo_laser_joint" type="fixed">
            <origin rpy="0 0 0" xyz="0 -0.0895 0.1726" />
            <parent link="barista_body" />
            <child link="hokuyo_laser_link" />
        </joint>

        <xacro:laser_scanner />
    </xacro:if>

    <!-- Right Motor Wheel -->

    <joint name="barista_body_right_motor_wheel_joint" type="continuous">
        <origin rpy="0 0 0" xyz="0.155 0 0.0352" />
        <parent link="barista_body" />
        <child link="right_motor_wheel" />
        <axis xyz="1 0 0" />
    </joint>

    <xacro:drive_wheel position="right" />

    <!-- Left Motor Wheel -->

    <joint name="barista_body_left_motor_wheel_joint" type="continuous">
        <origin rpy="0 0 0" xyz="-0.155 0 0.0352" />
        <parent link="barista_body" />
        <child link="left_motor_wheel" />
        <axis xyz="1 0 0" />
    </joint>

   <xacro:drive_wheel position="left" />

    <!-- Back Caster Wheel -->

    <joint name="barista_body_back_caster_wheel_joint" type="continuous">
        <origin rpy="0 0 0" xyz="0 0.135 0.0352" />
        <parent link="barista_body" />
        <child link="back_caster_wheel" />
        <axis xyz="1 0 0" />
    </joint>

    <xacro:caster_wheel position="back" />

    <!-- Front Caster Wheel -->

    <joint name="barista_body_front_caster_wheel_joint" type="continuous">
        <origin rpy="0 0 0" xyz="0 -0.135 0.0352" />
        <parent link="barista_body" />
        <child link="front_caster_wheel" />
        <axis xyz="1 0 0" />
    </joint>

    <xacro:caster_wheel position="front" />

    <!-- Standoff Rod One -->

    <joint name="barista_body_standoff_rod_one_joint" type="fixed">
        <origin rpy="0 0 0" xyz="0.0895 0.0543 0.1726" />
        <parent link="barista_body" />
        <child link="standoff_rod_one" />
    </joint>

    <xacro:standoff_rod id="one" width="0.01" length="0.22" />

    <!-- Standoff Rod Two -->

    <joint name="barista_body_standoff_rod_two_joint" type="fixed">
        <origin rpy="0 0 0" xyz="0.0895 -0.0543 0.1726" />
        <parent link="barista_body" />
        <child link="standoff_rod_two" />
    </joint>

    <xacro:standoff_rod id="two" width="0.01" length="0.22" />

    <!-- Standoff Rod Three -->

    <joint name="barista_body_standoff_rod_three_joint" type="fixed">
        <origin rpy="0 0 0" xyz="-0.0895 0.0543 0.1726" />
        <parent link="barista_body" />
        <child link="standoff_rod_three" />
    </joint>

    <xacro:standoff_rod id="three" width="0.01" length="0.22" />

    <!-- Standoff Rod Four -->

    <joint name="barista_body_standoff_rod_four_joint" type="fixed">
        <origin rpy="0 0 0" xyz="-0.0895 -0.0543 0.1726" />
        <parent link="barista_body" />
        <child link="standoff_rod_four" />
    </joint>

    <xacro:standoff_rod id="four" width="0.01" length="0.22" />

    <!-- Cup Holder Tray -->

    <joint name="barista_body_cup_holder_joint" type="fixed">
        <origin rpy="0 0 0" xyz="0 0 0.4376" />
        <parent link="barista_body" />
        <child link="cup_holder_tray" />
    </joint>

    <xacro:cup_holder_tray />

    <!-- Gazebo Plugin References -->

    <gazebo>
        <link name="front_caster_wheel">
            <surface>
            <friction>
                <ode>
                <mu>0.01</mu>
                <mu2>0.01</mu2>
                </ode>
            </friction>
            </surface>
        </link>
    </gazebo>

    <gazebo>
        <plugin filename="libgazebo_ros_diff_drive.so" name="differential_drive_controller">
            <left_joint>barista_body_left_motor_wheel_joint</left_joint>
            <right_joint>barista_body_right_motor_wheel_joint</right_joint>
            
            <wheel_separation>0.31</wheel_separation>
            <wheel_diameter>0.0704</wheel_diameter>
            
            <max_wheel_torque>1.0</max_wheel_torque>
            <max_wheel_acceleration>2.0</max_wheel_acceleration>

            <publish_odom>true</publish_odom>
            <publish_odom_tf>true</publish_odom_tf>

            <odometry_frame>odom</odometry_frame>
            <robot_base_frame>base_link</robot_base_frame>
        </plugin>
    </gazebo>

    <gazebo reference="hokuyo_laser_link">
        <sensor name="sensor_ray" type="ray">
            <pose>0 0 0 0 0 0</pose>
            <ray>
            <scan>
                <horizontal>
                <samples>200</samples>
                <resolution>1.0</resolution>
                <min_angle>-3.14</min_angle>
                <max_angle>3.14</max_angle>
                </horizontal>
            </scan>
            <range>
                <min>0.1</min>
                <max>5.0</max>
            </range>
            </ray>
            <always_on>true</always_on>
            <visualize>true</visualize>
            <update_rate>100.0</update_rate>
            <plugin name="laser" filename="libgazebo_ros_ray_sensor.so">
            <ros>
                <namespace>/</namespace>
                <remapping>~/out:=scan</remapping>
            </ros>
            <output_type>sensor_msgs/LaserScan</output_type>
            </plugin>
        </sensor>
    </gazebo>

    <!--Gazebo Color References -->

    <gazebo reference="right_motor_wheel">
        <material>Gazebo/DarkGrey</material>
    </gazebo>

    <gazebo reference="left_motor_wheel">
        <material>Gazebo/DarkGrey</material>
    </gazebo>

    <gazebo reference="standoff_rod_one">
        <material>Gazebo/Grey</material>
    </gazebo>

    <gazebo reference="standoff_rod_two">
        <material>Gazebo/Grey</material>
    </gazebo>

    <gazebo reference="standoff_rod_three">
        <material>Gazebo/Grey</material>
    </gazebo>

    <gazebo reference="standoff_rod_four">
        <material>Gazebo/Grey</material>
    </gazebo>

    <gazebo reference="barista_body">
        <material>Gazebo/SkyBlue</material>
    </gazebo>

    <gazebo reference="cup_holder_tray">
        <material>Gazebo/SkyBlue</material>
    </gazebo>
</robot>