<?xml version="1.0"?>
<robot name="barista_bot">
    <link name="base_link" />

    <joint name="base_barista_body_joint" type="fixed">
        <origin rpy="0 0 0" xyz="0 0 0" />
        <parent link="base_link" />
        <child link="barista_body" />
    </joint>

    <link name="barista_body">
        <visual>
            <origin rpy="0 0 0" xyz="0 0 0.0981" />
            <geometry>
                <cylinder radius="0.179" length="0.155" />
            </geometry>
            <material name="Cyan">
                <color rgba="0 1.0 1.0 1.0"/>
            </material>
        </visual>

        <collision>
            <origin rpy="0 0 0" xyz="0 0 0" />
            <geometry>
                <cylinder radius="0.179" length="0.155" />
            </geometry>
        </collision>

        <interial>
            <origin rpy="0 0 0" xyz="0 0 0" />
            <mass value="10.0" />
            <inertia ixx="0.100123333" ixy="0" ixz="0" iyy="0.100123333" iyz="0" izz="0.160205" />
        </interial>
    </link>

    <!-- Hokuyo Laser -->

    <joint name="barista_body_hokuyo_laser_joint" type="fixed">
        <origin rpy="0 0 0" xyz="0 -0.0895 0.1726" />
        <parent link="barista_body" />
        <child link="hokuyo_laser_link" />
    </joint>

    <link name="hokuyo_laser_link">
        <visual>
            <origin rpy="0 0 0" xyz="0 0 0" />
            <geometry>
                <mesh filename="package://barista_robot_description/meshes/hokuyo_urg_04lx.dae" />
            </geometry>
        </visual>

        <collision>
            <origin rpy="0 0 0" xyz="0 0 0" />
            <geometry>
                <mesh filename="package://barista_robot_description/meshes/hokuyo_urg_04lx.dae" />
            </geometry>
        </collision>

         <interial>
            <origin rpy="0 0 0" xyz="0 0 0" />
            <mass value="1.5" />
            <inertia ixx="0.0625" ixy="0" ixz="0" iyy="0.0625" iyz="0" izz="0.0625" />
        </interial>
    </link>
    
    <!-- Right Motor Wheel -->

    <joint name="barista_body_right_motor_wheel_joint" type="continuous">
        <origin rpy="0 0 0" xyz="0.155 0 0.0352" />
        <parent link="barista_body" />
        <child link="right_motor_wheel" />
        <axis xyz="1 0 0" />
    </joint>

    <link name="right_motor_wheel">
        <visual>
            <origin rpy="0 1.57 0" xyz="0 0 0" />
            <geometry>
                <cylinder radius="0.0352" length="0.0206" />
            </geometry>
            <material name="black">
                <color rgba="0 0 0 1"/>
            </material>
        </visual>

         <collision>
            <origin rpy="0 0 0" xyz="0 0 0" />
            <geometry>
                <cylinder radius="0.0352" length="0.0206" />
            </geometry>
        </collision>

        <interial>
            <origin rpy="0 0 0" xyz="0 0 0" />
            <mass value="2.5" />
            <inertia ixx="0.000862808" ixy="0" ixz="0" iyy="0.000862808" iyz="0" izz="0.0015488" />
        </interial>
    </link>

    
    <!-- Left Motor Wheel -->

    <joint name="barista_body_left_motor_wheel_joint" type="continuous">
        <origin rpy="0 0 0" xyz="-0.155 0 0.0352" />
        <parent link="barista_body" />
        <child link="left_motor_wheel" />
        <axis xyz="1 0 0" />
    </joint>

    <link name="left_motor_wheel">
        <visual>
            <origin rpy="0 1.57 0" xyz="0 0 0" />
            <geometry>
                <cylinder radius="0.0352" length="0.0206" />
            </geometry>
            <material name="black">
                <color rgba="0 0 0 1"/>
            </material>
        </visual>

         <collision>
            <origin rpy="0 0 0" xyz="0 0 0" />
            <geometry>
                <cylinder radius="0.0352" length="0.0206" />
            </geometry>
        </collision>

        <interial>
            <origin rpy="0 0 0" xyz="0 0 0" />
            <mass value="2.5" />
            <inertia ixx="0.000862808" ixy="0" ixz="0" iyy="0.000862808" iyz="0" izz="0.0015488" />
        </interial>
    </link>

    <!-- Front Caster Wheel -->

    <joint name="barista_body_front_caster_wheel_joint" type="fixed">
        <origin rpy="0 0 0" xyz="0 0.1198 0.0352" />
        <parent link="barista_body" />
        <child link="front_caster_wheel" />
    </joint>

    <link name="front_caster_wheel">
        <visual>
            <origin rpy="0 0 0" xyz="0 0 0" />
            <geometry>
                <sphere radius="0.0352"/>
            </geometry>
             <material name="Gray">
                <color rgba="0.5 0.5 0.5 1.0"/>
            </material>
        </visual>

         <collision>
             <origin rpy="0 0 0" xyz="0 0 0" />
            <geometry>
                <sphere radius="0.0352"/>
            </geometry>
        </collision>

        <interial>
            <origin rpy="0 0 0" xyz="0 0 0" />
            <mass value="1.5" />
            <inertia ixx="0.000743424" ixy="0" ixz="0" iyy="0.000743424" iyz="0" izz="0.000743424" />
        </interial>
    </link>

    <!-- Back Caster Wheel -->

    <joint name="barista_body_back_caster_wheel_joint" type="fixed">
        <origin rpy="0 0 0" xyz="0 -0.1198 0.0352" />
        <parent link="barista_body" />
        <child link="back_caster_wheel" />
    </joint>

    <link name="back_caster_wheel">
        <visual>
            <origin rpy="0 0 0" xyz="0 0 0" />
            <geometry>
                <sphere radius="0.0352"/>
            </geometry>
            <material name="Gray">
                <color rgba="0.5 0.5 0.5 1.0"/>
            </material>
        </visual>

         <collision>
             <origin rpy="0 0 0" xyz="0 0 0" />
            <geometry>
                <sphere radius="0.0352"/>
            </geometry>
        </collision>

        <interial>
            <origin rpy="0 0 0" xyz="0 0 0" />
            <mass value="1.5" />
            <inertia ixx="0.000743424" ixy="0" ixz="0" iyy="0.000743424" iyz="0" izz="0.000743424" />
        </interial>
    </link>

    <!-- Standoff Rod One -->

    <joint name="barista_body_standoff_rod_one_joint" type="fixed">
        <origin rpy="0 0 0" xyz="0.0895 0.0543 0.1726" />
        <parent link="barista_body" />
        <child link="standoff_rod_one" />
    </joint>

    <link name="standoff_rod_one">
        <visual>
            <origin rpy="0 0 0" xyz="0 0 0.11" />
            <geometry>
                <cylinder radius="0.01" length="0.22" />
            </geometry>
            <material name="Gray">
                <color rgba="0.5 0.5 0.5 1.0"/>
            </material>
        </visual>

        <collision>
            <origin rpy="0 0 0" xyz="0 0 0" />
            <geometry>
                <cylinder radius="0.01" length="0.22" />
            </geometry>
        </collision>

        <interial>
            <origin rpy="0 0 0" xyz="0 0 0" />
            <mass value="1.5" />
            <inertia ixx="0.0060875" ixy="0" ixz="0" iyy="0.0060875" iyz="0" izz="0.000075" />
        </interial>
    </link>

    <!-- Standoff Rod Two -->

    <joint name="barista_body_standoff_rod_two_joint" type="fixed">
        <origin rpy="0 0 0" xyz="0.0895 -0.0543 0.1726" />
        <parent link="barista_body" />
        <child link="standoff_rod_two" />
    </joint>

    <link name="standoff_rod_two">
        <visual>
            <origin rpy="0 0 0" xyz="0 0 0.11" />
            <geometry>
                <cylinder radius="0.01" length="0.22" />
            </geometry>
            <material name="Gray">
                <color rgba="0.5 0.5 0.5 1.0"/>
            </material>
        </visual>

        <collision>
            <origin rpy="0 0 0" xyz="0 0 0" />
            <geometry>
                <cylinder radius="0.01" length="0.22" />
            </geometry>
        </collision>

        <interial>
            <origin rpy="0 0 0" xyz="0 0 0" />
            <mass value="1.5" />
            <inertia ixx="0.0060875" ixy="0" ixz="0" iyy="0.0060875" iyz="0" izz="0.000075" />
        </interial>
    </link>

    <!-- Standoff Rod Three -->

    <joint name="barista_body_standoff_rod_three_joint" type="fixed">
        <origin rpy="0 0 0" xyz="-0.0895 0.0543 0.1726" />
        <parent link="barista_body" />
        <child link="standoff_rod_three" />
    </joint>

    <link name="standoff_rod_three">
        <visual>
            <origin rpy="0 0 0" xyz="0 0 0.11" />
            <geometry>
                <cylinder radius="0.01" length="0.22" />
            </geometry>
            <material name="Gray">
                <color rgba="0.5 0.5 0.5 1.0"/>
            </material>
        </visual>

        <collision>
            <origin rpy="0 0 0" xyz="0 0 0" />
            <geometry>
                <cylinder radius="0.01" length="0.22" />
            </geometry>
        </collision>

        <interial>
            <origin rpy="0 0 0" xyz="0 0 0" />
            <mass value="1.5" />
            <inertia ixx="0.0060875" ixy="0" ixz="0" iyy="0.0060875" iyz="0" izz="0.000075" />
        </interial>
    </link>

    <!-- Standoff Rod Four -->

    <joint name="barista_body_standoff_rod_four_joint" type="fixed">
        <origin rpy="0 0 0" xyz="-0.0895 -0.0543 0.1726" />
        <parent link="barista_body" />
        <child link="standoff_rod_four" />
    </joint>

    <link name="standoff_rod_four">
        <visual>
            <origin rpy="0 0 0" xyz="0 0 0.11" />
            <geometry>
                <cylinder radius="0.01" length="0.22" />
            </geometry>
            <material name="Gray">
                <color rgba="0.5 0.5 0.5 1.0"/>
            </material>
        </visual>

        <collision>
            <origin rpy="0 0 0" xyz="0 0 0" />
            <geometry>
                <cylinder radius="0.01" length="0.22" />
            </geometry>
        </collision>

        <interial>
            <origin rpy="0 0 0" xyz="0 0 0" />
            <mass value="1.5" />
            <inertia ixx="0.0060875" ixy="0" ixz="0" iyy="0.0060875" iyz="0" izz="0.000075" />
        </interial>
    </link>

    <!-- Barista Top -->
    
    <joint name="barista_body_barista_top_joint" type="fixed">
        <origin rpy="0 0 0" xyz="0 0 0.4376" />
        <parent link="barista_body" />
        <child link="barista_top" />
    </joint>

    <link name="barista_top">
        <visual>
            <origin rpy="0 0 0" xyz="0 0 0" />
            <geometry>
                <cylinder radius="0.179" length="0.09" />
            </geometry>
            <material name="Cyan">
                <color rgba="0 1.0 1.0 1.0"/>
            </material>
        </visual>

        <collision>
            <origin rpy="0 0 0" xyz="0 0 0" />
            <geometry>
                <cylinder radius="0.179" length="0.09" />
            </geometry>
        </collision>

        <interial>
            <origin rpy="0 0 0" xyz="0 0 0" />
            <mass value="5" />
            <inertia ixx="0.04342625" ixy="0" ixz="0" iyy="0.04342625" iyz="0" izz="0.0801025" />
        </interial>
    </link>
</robot>